Workbook

Sheet README
A1: GenAI Masterclass — Progress Tracker Workbook
A3: How to use
A4: 1. Open Dashboard. Set G5 = your current week number.
A5: 2. Change Status only on Modules, SystemDesign, LeadershipCareer, Projects, Interviews, STAR.
A6: 3. Log study sessions on DailyLog (enter Module Code; Title/Week auto-fill).
A7: 4. Weekly Progress % and Dashboard KPIs calculate automatically.
A9: Groups / subgroups / links
A10: Group = major section (01 LLM Engineering, 04 RAG, …)
A11: Subgroup = topic cluster inside a group
A12: Modules.Week ↔ Weekly.Module Codes (same codes)
A13: DailyLog.Module Code → VLOOKUP Title + Week from Modules
A14: Projects.Week + Linked Module Codes ↔ Weekly / Modules
... A32: Open in Excel or upload to Google Sheets / Drive. See Workflow sheet.

Sheet Dashboard
A1: GenAI Masterclass Dashboard
A2: Yellow cell G5 = current week. Update Status on other sheets; this page calculates.
A3: Track | B3: IC
A5: KPIs | F5: This Week Focus
A6: Modules Done+IR | B6: =COUNTIF(Modules!I:I,"Done")+COUNTIF(Modules!I:I,"Interview-ready") | F6: Week # → | G6: 0
A7: Modules Total | B7: 48 | F7: Theme | G7: =IFERROR(VLOOKUP($G$6,Weekly!A:B,2,FALSE),"")
A8: Module Progress % | B8: =IF(B7=0,0,B6/B7) | F8: Modules | G8: =IFERROR(VLOOKUP($G$6,Weekly!A:D,4,FALSE),"")
A9: Projects Done+IR | B9: =COUNTIF(Projects!F:F,"Done")+COUNTIF(Projects!F:F,"Interview-ready") | F9: Project | G9: =IFERROR(VLOOKUP($G$6,Weekly!A:E,5,FALSE),"")
A10: Projects Total | B10: 15 | F10: Interview focus | G10: =IFERROR(VLOOKUP($G$6,Weekly!A:F,6,FALSE),"")
A11: Mocks Done | B11: =COUNTIF(Interviews!L:L,"Done") | F11: Week Progress % | G11: =IFERROR(VLOOKUP($G$6,Weekly!A:L,12,FALSE),"")
A12: STAR Ready+ | B12: =COUNTIF(STAR!F:F,"Ready")+COUNTIF(STAR!F:F,"Interview-polished")
A13: Hours Logged (min) | B13: =SUM(DailyLog!J:J) | F13: Next 5 Modules
F14: Code | G14: Title | H14: Group | I14: Week
A15: Progress by Group | F15: =IFERROR(INDEX(_Helper!A:A,MATCH(1,_Helper!G:G,0)),"") | G15: =IFERROR(INDEX(_Helper!B:B,MATCH(1,_Helper!G:G,0)),"") | H15: =IFERROR(INDEX(_Helper!C:C,MATCH(1,_Helper!G:G,0)),"") | I15: =IFERROR(INDEX(_Helper!D:D,MATCH(1,_Helper!G:G,0)),"")
A16: Group | B16: Total | C16: Done+IR | D16: Progress % | F16: =IFERROR(INDEX(_Helper!A:A,MATCH(2,_Helper!G:G,0)),"") | G16: =IFERROR(INDEX(_Helper!B:B,MATCH(2,_Helper!G:G,0)),"") | H16: =IFERROR(INDEX(_Helper!C:C,MATCH(2,_Helper!G:G,0)),"") | I16: =IFERROR(INDEX(_Helper!D:D,MATCH(2,_Helper!G:G,0)),"")
A17: 00 Foundations | B17: =COUNTIF(Modules!C:C,A17) | C17: =COUNTIFS(Modules!C:C,A17,Modules!I:I,"Done")+COUNTIFS(Modules!C:C,A17,Modules!I:I,"Interview-ready") | D17: =IF(B17=0,0,C17/B17) | F17: =IFERROR(INDEX(_Helper!A:A,MATCH(3,_Helper!G:G,0)),"") | G17: =IFERROR(INDEX(_Helper!B:B,MATCH(3,_Helper!G:G,0)),"") | H17: =IFERROR(INDEX(_Helper!C:C,MATCH(3,_Helper!G:G,0)),"") | I17: =IFERROR(INDEX(_Helper!D:D,MATCH(3,_Helper!G:G,0)),"")
A18: 01 LLM Engineering | B18: =COUNTIF(Modules!C:C,A18) | C18: =COUNTIFS(Modules!C:C,A18,Modules!I:I,"Done")+COUNTIFS(Modules!C:C,A18,Modules!I:I,"Interview-ready") | D18: =IF(B18=0,0,C18/B18) | F18: =IFERROR(INDEX(_Helper!A:A,MATCH(4,_Helper!G:G,0)),"") | G18: =IFERROR(INDEX(_Helper!B:B,MATCH(4,_Helper!G:G,0)),"") | H18: =IFERROR(INDEX(_Helper!C:C,MATCH(4,_Helper!G:G,0)),"") | I18: =IFERROR(INDEX(_Helper!D:D,MATCH(4,_Helper!G:G,0)),"")
A19: 02 Prompt Engineering | B19: =COUNTIF(Modules!C:C,A19) | C19: =COUNTIFS(Modules!C:C,A19,Modules!I:I,"Done")+COUNTIFS(Modules!C:C,A19,Modules!I:I,"Interview-ready") | D19: =IF(B19=0,0,C19/B19) | F19: =IFERROR(INDEX(_Helper!A:A,MATCH(5,_Helper!G:G,0)),"") | G19: =IFERROR(INDEX(_Helper!B:B,MATCH(5,_Helper!G:G,0)),"") | H19: =IFERROR(INDEX(_Helper!C:C,MATCH(5,_Helper!G:G,0)),"") | I19: =IFERROR(INDEX(_Helper!D:D,MATCH(5,_Helper!G:G,0)),"")
A20: 03 Agentic Fundamentals | B20: =COUNTIF(Modules!C:C,A20) | C20: =COUNTIFS(Modules!C:C,A20,Modules!I:I,"Done")+COUNTIFS(Modules!C:C,A20,Modules!I:I,"Interview-ready") | D20: =IF(B20=0,0,C20/B20)
A21: 04 RAG | B21: =COUNTIF(Modules!C:C,A21) | C21: =COUNTIFS(Modules!C:C,A21,Modules!I:I,"Done")+COUNTIFS(Modules!C:C,A21,Modules!I:I,"Interview-ready") | D21: =IF(B21=0,0,C21/B21) | F21: Jump to sheet
A22: 05 Multi-Agent | B22: =COUNTIF(Modules!C:C,A22) | C22: =COUNTIFS(Modules!C:C,A22,Modules!I:I,"Done")+COUNTIFS(Modules!C:C,A22,Modules!I:I,"Interview-ready") | D22: =IF(B22=0,0,C22/B22) | F22: Workflow
A23: 06 Voice & Multimodal | B23: =COUNTIF(Modules!C:C,A23) | C23: =COUNTIFS(Modules!C:C,A23,Modules!I:I,"Done")+COUNTIFS(Modules!C:C,A23,Modules!I:I,"Interview-ready") | D23: =IF(B23=0,0,C23/B23) | F23: Config
A24: 07 Protocols MCP/A2A | B24: =COUNTIF(Modules!C:C,A24) | C24: =COUNTIFS(Modules!C:C,A24,Modules!I:I,"Done")+COUNTIFS(Modules!C:C,A24,Modules!I:I,"Interview-ready") | D24: =IF(B24=0,0,C24/B24) | F24: Modules
A25: 08 Eval & LLMOps | B25: =COUNTIF(Modules!C:C,A25) | C25: =COUNTIFS(Modules!C:C,A25,Modules!I:I,"Done")+COUNTIFS(Modules!C:C,A25,Modules!I:I,"Interview-ready") | D25: =IF(B25=0,0,C25/B25) | F25: Resources
A26: 09 Fine-Tuning | B26: =COUNTIF(Modules!C:C,A26) | C26: =COUNTIFS(Modules!C:C,A26,Modules!I:I,"Done")+COUNTIFS(Modules!C:C,A26,Modules!I:I,"Interview-ready") | D26: =IF(B26=0,0,C26/B26) | F26: Weekly
A27: 10 Production Infra | B27: =COUNTIF(Modules!C:C,A27) | C27: =COUNTIFS(Modules!C:C,A27,Modules!I:I,"Done")+COUNTIFS(Modules!C:C,A27,Modules!I:I,"Interview-ready") | D27: =IF(B27=0,0,C27/B27) | F27: DailyLog
A28: 11 Security & Safety | B28: =COUNTIF(Modules!C:C,A28) | C28: =COUNTIFS(Modules!C:C,A28,Modules!I:I,"Done")+COUNTIFS(Modules!C:C,A28,Modules!I:I,"Interview-ready") | D28: =IF(B28=0,0,C28/B28) | F28: Projects
A29: 12 Advanced Topics | B29: =COUNTIF(Modules!C:C,A29) | C29: =COUNTIFS(Modules!C:C,A29,Modules!I:I,"Done")+COUNTIFS(Modules!C:C,A29,Modules!I:I,"Interview-ready") | D29: =IF(B29=0,0,C29/B29) | F29: Interviews
F30: STAR
A31: Projects by Tier | F31: Tip: On Modules sheet use the filter arrows on Group / Subgroup / Status / Week.
A32: Tier | B32: Total | C32: Done+IR | D32: Progress % | F32: Tip: Filter Projects by Tier for a board-like pipeline.
A33: Mini | B33: =COUNTIF(Projects!D:D,A33) | C33: =COUNTIFS(Projects!D:D,A33,Projects!F:F,"Done")+COUNTIFS(Projects!D:D,A33,Projects!F:F,"Interview-ready") | D33: =IF(B33=0,0,C33/B33)
A34: Intermediate | B34: =COUNTIF(Projects!D:D,A34) | C34: =COUNTIFS(Projects!D:D,A34,Projects!F:F,"Done")+COUNTIFS(Projects!D:D,A34,Projects!F:F,"Interview-ready") | D34: =IF(B34=0,0,C34/B34)
A35: Production | B35: =COUNTIF(Projects!D:D,A35) | C35: =COUNTIFS(Projects!D:D,A35,Projects!F:F,"Done")+COUNTIFS(Projects!D:D,A35,Projects!F:F,"Interview-ready") | D35: =IF(B35=0,0,C35/B35)
A36: Capstone | B36: =COUNTIF(Projects!D:D,A36) | C36: =COUNTIFS(Projects!D:D,A36,Projects!F:F,"Done")+COUNTIFS(Projects!D:D,A36,Projects!F:F,"Interview-ready") | D36: =IF(B36=0,0,C36/B36)
A38: Interview Pipeline
A39: Planned | B39: =COUNTIF(Interviews!L:L,"Planned")
A40: Done | B40: =COUNTIF(Interviews!L:L,"Done")
A41: Needs retest | B41: =COUNTIF(Interviews!L:L,"Needs retest")
A42: Avg Score (Done) | B42: =IFERROR(AVERAGEIF(Interviews!L:L,"Done",Interviews!E:E),"")

Sheet Config
A1: Config — Doc / Resource linking
A3: Setting | B3: Value
A4: Local Root | B4: /workspace/
A5: GitHub Base | B5: https://github.com/rcrahul43/GenAI-Masterclass/blob/main/
A6: Link Mode | B6: Local
A8: How linking works
A9: Local mode: Open Doc uses file:// + Local Root + File Path (works in Excel on this Mac).
A10: GitHub mode: push this folder to a repo, set GitHub Base, set Link Mode=GitHub (works in Sheets too).
A11: Resources!URL always opens the external docs/papers (no doc required).
A12: Re-sync resources from handbook: run python Tracker/build_tracker_xlsx.py
A14: Google Sheets tip
A15: Upload xlsx to Drive → Open with Google Sheets. Use Link Mode=GitHub for clickable docs.
A16: Keep progress columns (Status, minutes, Done?) only in the Sheet — don’t duplicate in markdown.

Sheet Workflow
A1: Sheet ↔ Doc ↔ Resource workflow
A3: Goal
A4: Sheet = progress dashboard. Doc = deep reading when needed. Resource URL = quick official link.
A6: Path A — study with depth
A7: Dashboard / Modules → set Status=In progress → click Open Doc → read chapter → open Further Reading from doc OR from Resources sheet → mark Status=Done
A9: Path B — no doc needed
A10: Modules → note Item ID → Resources filter Item ID → click URL → mark Resources Done?=Yes → optionally mark module Done if that was enough
A12: What syncs automatically
A13: Handbook Further Reading → Resources sheet (when you re-run build_tracker_xlsx.py)
A14: Modules Resource Count ← formula into Resources
A15: DailyLog Title/Week ← VLOOKUP Modules
A16: Weekly Progress % ← formulas from Modules Status
... A28: Treat Sheet Status as sacred: before rebuild, copy Modules!A:I to a backup tab, rebuild, then paste Status back by Module Code.

Sheet Lookups
A1: Status | B1: Track | C1: Tier | D1: MockType | E1: YesNo | F1: STAR Pattern
A2: Not started | B2: IC | C2: Mini | D2: Senior AI | E2: Yes | F2: Project Experience
A3: In progress | B3: EM | C3: Intermediate | D3: Staff AI | E3: No | F3: Conflict Resolution
A4: Done | B4: Hybrid | C4: Production | D4: Principal Design | F4: Execution
A5: Interview-ready | B5: IC+EM | C5: Capstone | D5: EM Behavioral | F5: Hiring
D6: Staff+Security | F6: Technical Judgment
D7: EM Execution | F7: Cross-Functional
D8: Full Panel | F8: Leadership Profile
D9: Offer Rehearsal | F9: Personal Growth

Sheet Modules
A1: Module Code | B1: Title | C1: Group | D1: Subgroup | E1: Section Order | F1: Week | G1: Track | H1: Est Hours | I1: Status | J1: Minutes Spent | K1: Lab Done | L1: Judgment Memo | M1: Interview Drill | N1: Next Action | O1: File Path | P1: Open Doc | Q1: Notes | R1: Resource Count
A2: 00-01 | B2: 00-01 — GenAI From Scratch: Core Ideas | C2: 00 Foundations | D2: Foundations | E2: 0 | F2: 0 | G2: IC+EM | H2: 4 | I2: Not started | K2: No | L2: No | M2: No | O2: Modules/00-Foundations/00-01-GenAI-From-Scratch.md | P2: =IF(O2="","",IF(Config!$B$6="GitHub",HYPERLINK(Config!$B$5&O2,"Open doc"),HYPERLINK("file://"&Config!$B$4&O2,"Open doc"))) | R2: =COUNTIFS(Resources!A:A,"Module",Resources!B:B,A2)
A3: 00-02 | B3: 00-02 — Python for AI Engineering | C3: 00 Foundations | D3: Foundations | E3: 0 | F3: 0 | G3: IC+EM | H3: 8 | I3: Not started | K3: No | L3: No | M3: No | O3: Modules/00-Foundations/00-02-Python-for-AI-Engineering.md | P3: =IF(O3="","",IF(Config!$B$6="GitHub",HYPERLINK(Config!$B$5&O3,"Open doc"),HYPERLINK("file://"&Config!$B$4&O3,"Open doc"))) | R3: =COUNTIFS(Resources!A:A,"Module",Resources!B:B,A3)
A4: 00-03 | B4: 00-03 — APIs for AI Engineering | C4: 00 Foundations | D4: Foundations | E4: 0 | F4: 0 | G4: IC+EM | H4: 8 | I4: Not started | K4: No | L4: No | M4: No | O4: Modules/00-Foundations/00-03-APIs-for-AI-Engineering.md | P4: =IF(O4="","",IF(Config!$B$6="GitHub",HYPERLINK(Config!$B$5&O4,"Open doc"),HYPERLINK("file://"&Config!$B$4&O4,"Open doc"))) | R4: =COUNTIFS(Resources!A:A,"Module",Resources!B:B,A4)
A5: 00-04 | B5: 00-04 — From Rules to Agents: The Evolution of Intelligent Systems | C5: 00 Foundations | D5: Foundations | E5: 0 | F5: 1 | G5: IC+EM | H5: 8 | I5: Not started | K5: No | L5: No | M5: No | O5: Modules/00-Foundations/00-04-From-Rules-to-Agents.md | P5: =IF(O5="","",IF(Config!$B$6="GitHub",HYPERLINK(Config!$B$5&O5,"Open doc"),HYPERLINK("file://"&Config!$B$4&O5,"Open doc"))) | R5: =COUNTIFS(Resources!A:A,"Module",Resources!B:B,A5)
A6: 00-05 | B6: 00-05 — Mathematics for AI Engineering | C6: 00 Foundations | D6: Foundations | E6: 0 | F6: 1 | G6: IC+EM | H6: 7 | I6: Not started | K6: No | L6: No | M6: No | O6: Modules/00-Foundations/00-05-Mathematics-for-AI-Engineering.md | P6: =IF(O6="","",IF(Config!$B$6="GitHub",HYPERLINK(Config!$B$5&O6,"Open doc"),HYPERLINK("file://"&Config!$B$4&O6,"Open doc"))) | R6: =COUNTIFS(Resources!A:A,"Module",Resources!B:B,A6)
A7: 00-06 | B7: 00-06 — BankCo Warm-Up: Decision-Support Retention Assistant | C7: 00 Foundations | D7: Foundations | E7: 0 | F7: 1 | G7: IC+EM | H7: 6 | I7: Not started | K7: No | L7: No | M7: No | O7: Modules/00-Foundations/00-06-BankCo-Decision-Support-Warmup.md | P7: =IF(O7="","",IF(Config!$B$6="GitHub",HYPERLINK(Config!$B$5&O7,"Open doc"),HYPERLINK("file://"&Config!$B$4&O7,"Open doc"))) | R7: =COUNTIFS(Resources!A:A,"Module",Resources!B:B,A7)
A8: 01-01 | B8: 01-01 — Transformer Architecture for AI Engineers | C8: 01 LLM Engineering | D8: LLM Engineering | E8: 1 | F8: 2 | G8: IC | H8: 6 | I8: Not started | K8: No | L8: No | M8: No | O8: Modules/01-LLM-Engineering/01-01-Transformer-Architecture.md | P8: =IF(O8="","",IF(Config!$B$6="GitHub",HYPERLINK(Config!$B$5&O8,"Open doc"),HYPERLINK("file://"&Config!$B$4&O8,"Open doc"))) | R8: =COUNTIFS(Resources!A:A,"Module",Resources!B:B,A8)
A9: 01-02 | B9: 01-02 — Tokenization, Context Windows & Attention Economics | C9: 01 LLM Engineering | D9: LLM Engineering | E9: 1 | F9: 2 | G9: IC | H9: 6 | I9: Not started | K9: No | L9: No | M9: No | O9: Modules/01-LLM-Engineering/01-02-Tokenization-Context-Windows.md | P9: =IF(O9="","",IF(Config!$B$6="GitHub",HYPERLINK(Config!$B$5&O9,"Open doc"),HYPERLINK("file://"&Config!$B$4&O9,"Open doc"))) | R9: =COUNTIFS(Resources!A:A,"Module",Resources!B:B,A9)
A10: 01-03 | B10: 01-03 — Provider SDKs: OpenAI, Claude, Gemini & DeepSeek | C10: 01 LLM Engineering | D10: LLM Engineering | E10: 1 | F10: 3 | G10: IC | H10: 9 | I10: Not started | K10: No | L10: No | M10: No | O10: Modules/01-LLM-Engineering/01-03-Provider-SDKs-OpenAI-Claude-Gemini.md | P10: =IF(O10="","",IF(Config!$B$6="GitHub",HYPERLINK(Config!$B$5&O10,"Open doc"),HYPERLINK("file://"&Config!$B$4&O10,"Open doc"))) | R10: =COUNTIFS(Resources!A:A,"Module",Resources!B:B,A10)
A11: 01-04 | B11: 01-04 — Model Routing with LiteLLM | C11: 01 LLM Engineering | D11: LLM Engineering | E11: 1 | F11: 3 | G11: IC | H11: 8 | I11: Not started | K11: No | L11: No | M11: No | O11: Modules/01-LLM-Engineering/01-04-Model-Routing-LiteLLM.md | P11: =IF(O11="","",IF(Config!$B$6="GitHub",HYPERLINK(Config!$B$5&O11,"Open doc"),HYPERLINK("file://"&Config!$B$4&O11,"Open doc"))) | R11: =COUNTIFS(Resources!A:A,"Module",Resources!B:B,A11)
A12: 01-05 | B12: 01-05 — Inference Serving with vLLM, Ollama & Quantization | C12: 01 LLM Engineering | D12: LLM Engineering | E12: 1 | F12: 3 | G12: IC | H12: 6 | I12: Not started | K12: No | L12: No | M12: No | O12: Modules/01-LLM-Engineering/01-05-Inference-Serving-vLLM.md | P12: =IF(O12="","",IF(Config!$B$6="GitHub",HYPERLINK(Config!$B$5&O12,"Open doc"),HYPERLINK("file://"&Config!$B$4&O12,"Open doc"))) | R12: =COUNTIFS(Resources!A:A,"Module",Resources!B:B,A12)
A13: 02-01 | B13: 02-01 — Production Prompt Engineering | C13: 02 Prompt Engineering | D13: Prompt Engineering | E13: 2 | F13: 4 | G13: IC+EM | H13: 6 | I13: Not started | K13: No | L13: No | M13: No | O13: Modules/02-Prompt-Engineering/02-01-Production-Prompt-Engineering.md | P13: =IF(O13="","",IF(Config!$B$6="GitHub",HYPERLINK(Config!$B$5&O13,"Open doc"),HYPERLINK("file://"&Config!$B$4&O13,"Open doc"))) | R13: =COUNTIFS(Resources!A:A,"Module",Resources!B:B,A13)
... A49: 12-06 | B49: 12-06 — AI Product Thinking | C49: 12 Advanced Topics | D49: Advanced Topics | E49: 12 | F49: 16 | G49: IC | H49: 6 | I49: Not started | K49: No | L49: No | M49: No | O49: Modules/12-Advanced-Topics/12-06-AI-Product-Thinking.md | P49: =IF(O49="","",IF(Config!$B$6="GitHub",HYPERLINK(Config!$B$5&O49,"Open doc"),HYPERLINK("file://"&Config!$B$4&O49,"Open doc"))) | R49: =COUNTIFS(Resources!A:A,"Module",Resources!B:B,A49)

Sheet Resources
A1: Item Type | B1: Item ID | C1: Group | D1: Res # | E1: Title | F1: URL | G1: Open Resource | H1: Open Parent Doc | I1: Difficulty | J1: Reading Time | K1: Why Read | L1: Important Sections | M1: Source File | N1: Done? | O1: Notes
A2: Module | B2: 00-01 | C2: 00-Foundations | D2: 1 | E2: OpenAI — Text generation / chat concepts | F2: https://platform.openai.com/docs/guides/text | G2: =IF(F2="","",HYPERLINK(F2,"Open link")) | H2: =IF(M2="","",IF(Config!$B$6="GitHub",HYPERLINK(Config!$B$5&M2,"Open parent doc"),HYPERLINK("file://"&Config!$B$4&M2,"Open parent doc"))) | I2: Intro | J2: 20–30 min | K2: Solidify messages, models, tokens | L2: Messages; models; token basics | M2: Modules/00-Foundations/00-01-GenAI-From-Scratch.md | N2: No
A3: Module | B3: 00-01 | C3: 00-Foundations | D3: 2 | E3: Anthropic — Claude overview | F3: https://docs.anthropic.com/en/docs/welcome | G3: =IF(F3="","",HYPERLINK(F3,"Open link")) | H3: =IF(M3="","",IF(Config!$B$6="GitHub",HYPERLINK(Config!$B$5&M3,"Open parent doc"),HYPERLINK("file://"&Config!$B$4&M3,"Open parent doc"))) | I3: Intro | J3: 20 min | K3: Second provider vocabulary | L3: Messages API mental model | M3: Modules/00-Foundations/00-01-GenAI-From-Scratch.md | N3: No
A4: Module | B4: 00-01 | C4: 00-Foundations | D4: 3 | E4: Google — Gemini API quickstart | F4: https://ai.google.dev/gemini-api/docs/quickstart | G4: =IF(F4="","",HYPERLINK(F4,"Open link")) | H4: =IF(M4="","",IF(Config!$B$6="GitHub",HYPERLINK(Config!$B$5&M4,"Open parent doc"),HYPERLINK("file://"&Config!$B$4&M4,"Open parent doc"))) | I4: Intro | J4: 20 min | K4: Multi-provider habit early | L4: First request | M4: Modules/00-Foundations/00-01-GenAI-From-Scratch.md | N4: No
A5: Module | B5: 00-01 | C5: 00-Foundations | D5: 4 | E5: DeepSeek API docs | F5: https://api-docs.deepseek.com/ | G5: =IF(F5="","",HYPERLINK(F5,"Open link")) | H5: =IF(M5="","",IF(Config!$B$6="GitHub",HYPERLINK(Config!$B$5&M5,"Open parent doc"),HYPERLINK("file://"&Config!$B$4&M5,"Open parent doc"))) | I5: Intro | J5: 15 min | K5: Cost-efficient OpenAI-compatible option | L5: First chat call | M5: Modules/00-Foundations/00-01-GenAI-From-Scratch.md | N5: No
A6: Module | B6: 00-01 | C6: 00-Foundations | D6: 5 | E6: OpenAI Prompt Engineering Guide | F6: https://developers.openai.com/api/docs/guides/prompt-engineering | G6: =IF(F6="","",HYPERLINK(F6,"Open link")) | H6: =IF(M6="","",IF(Config!$B$6="GitHub",HYPERLINK(Config!$B$5&M6,"Open parent doc"),HYPERLINK("file://"&Config!$B$4&M6,"Open parent doc"))) | I6: Intro | J6: 45 min | K6: Prompts as clear instructions | L6: Tactics; iteration | M6: Modules/00-Foundations/00-01-GenAI-From-Scratch.md | N6: No
A7: Module | B7: 00-01 | C7: 00-Foundations | D7: 6 | E7: Chip Huyen — *AI Engineering* (book) | F7: https://www.oreilly.com/library/view/ai-engineering/9781098166298/ | G7: =IF(F7="","",HYPERLINK(F7,"Open link")) | H7: =IF(M7="","",IF(Config!$B$6="GitHub",HYPERLINK(Config!$B$5&M7,"Open parent doc"),HYPERLINK("file://"&Config!$B$4&M7,"Open parent doc"))) | I7: Intermediate | J7: ongoing | K7: Bridge from ideas to production later | L7: Early chapters on AI eng vs ML eng | M7: Modules/00-Foundations/00-01-GenAI-From-Scratch.md | N7: No
A8: Module | B8: 00-01 | C8: 00-Foundations | D8: 7 | E8: Karpathy — Intro to LLMs (talk) | F8: https://www.youtube.com/watch?v=zjkBMFhNj_g | G8: =IF(F8="","",HYPERLINK(F8,"Open link")) | H8: =IF(M8="","",IF(Config!$B$6="GitHub",HYPERLINK(Config!$B$5&M8,"Open parent doc"),HYPERLINK("file://"&Config!$B$4&M8,"Open parent doc"))) | I8: Intro | J8: 60 min | K8: Intuition without heavy math | L8: Whole talk once | M8: Modules/00-Foundations/00-01-GenAI-From-Scratch.md | N8: No
A9: Module | B9: 00-04 | C9: 00-Foundations | D9: 1 | E9: Attention Is All You Need (Transformers) | F9: https://arxiv.org/abs/1706.03762 | G9: =IF(F9="","",HYPERLINK(F9,"Open link")) | H9: =IF(M9="","",IF(Config!$B$6="GitHub",HYPERLINK(Config!$B$5&M9,"Open parent doc"),HYPERLINK("file://"&Config!$B$4&M9,"Open parent doc"))) | I9: Advanced | J9: 60–90 min | K9: Foundational architecture behind all modern LLMs; shared vocabulary for encoder/decoder and attention | L9: §3 Model Architecture; §3.2 Attention; Figure 1 | M9: Modules/00-Foundations/00-04-From-Rules-to-Agents.md | N9: No
A10: Module | B10: 00-04 | C10: 00-Foundations | D10: 2 | E10: ReAct: Synergizing Reasoning and Acting in Language Models | F10: https://arxiv.org/abs/2210.03629 | G10: =IF(F10="","",HYPERLINK(F10,"Open link")) | H10: =IF(M10="","",IF(Config!$B$6="GitHub",HYPERLINK(Config!$B$5&M10,"Open parent doc"),HYPERLINK("file://"&Config!$B$4&M10,"Open parent doc"))) | I10: Intermediate | J10: 45–60 min | K10: Research basis for Think → Act → Observe agent loops | L10: §1 Introduction; §3 ReAct Prompting; Figures 1–3 | M10: Modules/00-Foundations/00-04-From-Rules-to-Agents.md | N10: No
A11: Module | B11: 00-04 | C11: 00-Foundations | D11: 3 | E11: OpenAI Prompt Engineering Guide | F11: https://developers.openai.com/api/docs/guides/prompt-engineering | G11: =IF(F11="","",HYPERLINK(F11,"Open link")) | H11: =IF(M11="","",IF(Config!$B$6="GitHub",HYPERLINK(Config!$B$5&M11,"Open parent doc"),HYPERLINK("file://"&Config!$B$4&M11,"Open parent doc"))) | I11: Intro–Intermediate | J11: 45 min | K11: Official tactics for reliable prompts as API contracts | L11: Message roles; clear instructions; iterative development | M11: Modules/00-Foundations/00-04-From-Rules-to-Agents.md | N11: No
A12: Module | B12: 00-04 | C12: 00-Foundations | D12: 4 | E12: LangGraph High-Level Concepts | F12: https://langchain-ai.github.io/langgraph/concepts/high_level/ | G12: =IF(F12="","",HYPERLINK(F12,"Open link")) | H12: =IF(M12="","",IF(Config!$B$6="GitHub",HYPERLINK(Config!$B$5&M12,"Open parent doc"),HYPERLINK("file://"&Config!$B$4&M12,"Open parent doc"))) | I12: Intermediate | J12: 25–35 min | K12: Production agent runtime: persistence, HITL, state graphs | L12: Core benefits; persistence/checkpointing; when to use LangGraph | M12: Modules/00-Foundations/00-04-From-Rules-to-Agents.md | N12: No
A13: Module | B13: 00-04 | C13: 00-Foundations | D13: 5 | E13: Build with Claude (Anthropic Platform Overview) | F13: https://platform.claude.com/docs/en/docs/build-with-claude/overview | G13: =IF(F13="","",HYPERLINK(F13,"Open link")) | H13: =IF(M13="","",IF(Config!$B$6="GitHub",HYPERLINK(Config!$B$5&M13,"Open parent doc"),HYPERLINK("file://"&Config!$B$4&M13,"Open parent doc"))) | I13: Intro–Intermediate | J13: 30–45 min | K13: Provider comparison mindset; tool use and production constraints from a second major API | L13: Overview; tool use; messages API patterns | M13: Modules/00-Foundations/00-04-From-Rules-to-Agents.md | N13: No
... A149: Module | B149: 07-03 | C149: 07-Protocols-MCP-A2A | D149: 5 | E149: Enterprise Integration Patterns | F149: https://www.enterpriseintegrationpatterns.com/ | G149: =IF(F149="","",HYPERLINK(F149,"Open link")) | H149: =IF(M149="","",IF(Config!$B$6="GitHub",HYPERLINK(Config!$B$5&M149,"Open parent doc"),HYPERLINK("file://"&Config!$B$4&M149,"Open parent doc"))) | I149: Advanced | J149: 60 min | K149: Message routing | L149: Saga; DLQ | M149: Modules/07-Protocols-MCP-A2A/07-03-Negotiation-Async-Workflows.md | N149: No
A150: Module | B150: 07-04 | C150: 07-Protocols-MCP-A2A | D150: 1 | E150: https://modelcontextprotocol.io/ | F150: https://modelcontextprotocol.io/ | G150: =IF(F150="","",HYPERLINK(F150,"Open link")) | H150: =IF(M150="","",IF(Config!$B$6="GitHub",HYPERLINK(Config!$B$5&M150,"Open parent doc"),HYPERLINK("file://"&Config!$B$4&M150,"Open parent doc"))) | M150: Modules/07-Protocols-MCP-A2A/07-04-MCP-Production-Patterns.md | N150: No
A151: Module | B151: 07-04 | C151: 07-Protocols-MCP-A2A | D151: 2 | E151: https://spec.modelcontextprotocol.io/ | F151: https://spec.modelcontextprotocol.io/ | G151: =IF(F151="","",HYPERLINK(F151,"Open link")) | H151: =IF(M151="","",IF(Config!$B$6="GitHub",HYPERLINK(Config!$B$5&M151,"Open parent doc"),HYPERLINK("file://"&Config!$B$4&M151,"Open parent doc"))) | M151: Modules/07-Protocols-MCP-A2A/07-04-MCP-Production-Patterns.md | N151: No
A152: Module | B152: 07-04 | C152: 07-Protocols-MCP-A2A | D152: 3 | E152: https://github.com/modelcontextprotocol/python-sdk | F152: https://github.com/modelcontextprotocol/python-sdk | G152: =IF(F152="","",HYPERLINK(F152,"Open link")) | H152: =IF(M152="","",IF(Config!$B$6="GitHub",HYPERLINK(Config!$B$5&M152,"Open parent doc"),HYPERLINK("file://"&Config!$B$4&M152,"Open parent doc"))) | M152: Modules/07-Protocols-MCP-A2A/07-04-MCP-Production-Patterns.md | N152: No
A153: Module | B153: 07-04 | C153: 07-Protocols-MCP-A2A | D153: 4 | E153: https://docs.cursor.com/ | F153: https://docs.cursor.com/ | G153: =IF(F153="","",HYPERLINK(F153,"Open link")) | H153: =IF(M153="","",IF(Config!$B$6="GitHub",HYPERLINK(Config!$B$5&M153,"Open parent doc"),HYPERLINK("file://"&Config!$B$4&M153,"Open parent doc"))) | M153: Modules/07-Protocols-MCP-A2A/07-04-MCP-Production-Patterns.md | N153: No
A154: Module | B154: 07-04 | C154: 07-Protocols-MCP-A2A | D154: 5 | E154: https://support.anthropic.com/ | F154: https://support.anthropic.com/ | G154: =IF(F154="","",HYPERLINK(F154,"Open link")) | H154: =IF(M154="","",IF(Config!$B$6="GitHub",HYPERLINK(Config!$B$5&M154,"Open parent doc"),HYPERLINK("file://"&Config!$B$4&M154,"Open parent doc"))) | M154: Modules/07-Protocols-MCP-A2A/07-04-MCP-Production-Patterns.md | N154: No
A155: Module | B155: 07-04 | C155: 07-Protocols-MCP-A2A | D155: 6 | E155: https://www.openpolicyagent.org/docs/latest/ | F155: https://www.openpolicyagent.org/docs/latest/ | G155: =IF(F155="","",HYPERLINK(F155,"Open link")) | H155: =IF(M155="","",IF(Config!$B$6="GitHub",HYPERLINK(Config!$B$5&M155,"Open parent doc"),HYPERLINK("file://"&Config!$B$4&M155,"Open parent doc"))) | M155: Modules/07-Protocols-MCP-A2A/07-04-MCP-Production-Patterns.md | N155: No
A156: Module | B156: 07-04 | C156: 07-Protocols-MCP-A2A | D156: 7 | E156: https://owasp.org/www-project-top-10-for-large-language-model-applications/ | F156: https://owasp.org/www-project-top-10-for-large-language-model-applications/ | G156: =IF(F156="","",HYPERLINK(F156,"Open link")) | H156: =IF(M156="","",IF(Config!$B$6="GitHub",HYPERLINK(Config!$B$5&M156,"Open parent doc"),HYPERLINK("file://"&Config!$B$4&M156,"Open parent doc"))) | M156: Modules/07-Protocols-MCP-A2A/07-04-MCP-Production-Patterns.md | N156: No
A157: Module | B157: 08-01 | C157: 08-Evaluation-LLMOps | D157: 1 | E157: DeepEval Getting Started | F157: https://deepeval.com/docs/getting-started | G157: =IF(F157="","",HYPERLINK(F157,"Open link")) | H157: =IF(M157="","",IF(Config!$B$6="GitHub",HYPERLINK(Config!$B$5&M157,"Open parent doc"),HYPERLINK("file://"&Config!$B$4&M157,"Open parent doc"))) | I157: Intro | J157: 30 min | K157: GEval + CI | L157: Metrics; test cases | M157: Modules/08-Evaluation-LLMOps/08-01-Evaluation-Lifecycle.md | N157: No
A158: Module | B158: 08-01 | C158: 08-Evaluation-LLMOps | D158: 2 | E158: DeepEval GEval | F158: https://deepeval.com/docs/metrics-llm-evals | G158: =IF(F158="","",HYPERLINK(F158,"Open link")) | H158: =IF(M158="","",IF(Config!$B$6="GitHub",HYPERLINK(Config!$B$5&M158,"Open parent doc"),HYPERLINK("file://"&Config!$B$4&M158,"Open parent doc"))) | I158: Intermediate | J158: 35 min | K158: Custom criteria | L158: GEval setup | M158: Modules/08-Evaluation-LLMOps/08-01-Evaluation-Lifecycle.md | N158: No
A159: Module | B159: 08-01 | C159: 08-Evaluation-LLMOps | D159: 3 | E159: LangSmith Evaluation | F159: https://docs.smith.langchain.com/evaluation | G159: =IF(F159="","",HYPERLINK(F159,"Open link")) | H159: =IF(M159="","",IF(Config!$B$6="GitHub",HYPERLINK(Config!$B$5&M159,"Open parent doc"),HYPERLINK("file://"&Config!$B$4&M159,"Open parent doc"))) | I159: Intermediate | J159: 40 min | K159: Datasets + experiments | L159: Feedback | M159: Modules/08-Evaluation-LLMOps/08-01-Evaluation-Lifecycle.md | N159: No
A160: Module | B160: 08-01 | C160: 08-Evaluation-LLMOps | D160: 4 | E160: OpenAI Evals Guide | F160: https://platform.openai.com/docs/guides/evals | G160: =IF(F160="","",HYPERLINK(F160,"Open link")) | H160: =IF(M160="","",IF(Config!$B$6="GitHub",HYPERLINK(Config!$B$5&M160,"Open parent doc"),HYPERLINK("file://"&Config!$B$4&M160,"Open parent doc"))) | I160: Intermediate | J160: 35 min | K160: Benchmark mindset | L160: Best practices | M160: Modules/08-Evaluation-LLMOps/08-01-Evaluation-Lifecycle.md | N160: No
A161: Module | B161: 08-01 | C161: 08-Evaluation-LLMOps | D161: 5 | E161: HELM (Stanford) | F161: https://crfm.stanford.edu/helm/ | G161: =IF(F161="","",HYPERLINK(F161,"Open link")) | H161: =IF(M161="","",IF(Config!$B$6="GitHub",HYPERLINK(Config!$B$5&M161,"Open parent doc"),HYPERLINK("file://"&Config!$B$4&M161,"Open parent doc"))) | I161: Advanced | J161: 60 min | K161: Holistic eval framing | L161: Metrics taxonomy | M161: Modules/08-Evaluation-LLMOps/08-01-Evaluation-Lifecycle.md | N161: No
A162: Module | B162: 08-02 | C162: 08-Evaluation-LLMOps | D162: 1 | E162: LangSmith Docs | F162: https://docs.smith.langchain.com/ | G162: =IF(F162="","",HYPERLINK(F162,"Open link")) | H162: =IF(M162="","",IF(Config!$B$6="GitHub",HYPERLINK(Config!$B$5&M162,"Open parent doc"),HYPERLINK("file://"&Config!$B$4&M162,"Open parent doc"))) | I162: Intro | J162: 40 min | K162: Trace + eval | L162: Tracing; datasets | M162: Modules/08-Evaluation-LLMOps/08-02-Observability-LangSmith-OTel.md | N162: No
A163: Module | B163: 08-02 | C163: 08-Evaluation-LLMOps | D163: 2 | E163: LangSmith Tracing | F163: https://docs.smith.langchain.com/tracing | G163: =IF(F163="","",HYPERLINK(F163,"Open link")) | H163: =IF(M163="","",IF(Config!$B$6="GitHub",HYPERLINK(Config!$B$5&M163,"Open parent doc"),HYPERLINK("file://"&Config!$B$4&M163,"Open parent doc"))) | I163: Intermediate | J163: 35 min | K163: Setup | L163: Projects; runs | M163: Modules/08-Evaluation-LLMOps/08-02-Observability-LangSmith-OTel.md | N163: No
A164: Module | B164: 08-02 | C164: 08-Evaluation-LLMOps | D164: 3 | E164: OpenTelemetry Docs | F164: https://opentelemetry.io/docs/ | G164: =IF(F164="","",HYPERLINK(F164,"Open link")) | H164: =IF(M164="","",IF(Config!$B$6="GitHub",HYPERLINK(Config!$B$5&M164,"Open parent doc"),HYPERLINK("file://"&Config!$B$4&M164,"Open parent doc"))) | I164: Intermediate | J164: 45 min | K164: Platform APM | L164: Concepts; SDK | M164: Modules/08-Evaluation-LLMOps/08-02-Observability-LangSmith-OTel.md | N164: No
A165: Module | B165: 08-02 | C165: 08-Evaluation-LLMOps | D165: 4 | E165: OTel GenAI Semantics | F165: https://opentelemetry.io/docs/specs/semconv/gen-ai/ | G165: =IF(F165="","",HYPERLINK(F165,"Open link")) | H165: =IF(M165="","",IF(Config!$B$6="GitHub",HYPERLINK(Config!$B$5&M165,"Open parent doc"),HYPERLINK("file://"&Config!$B$4&M165,"Open parent doc"))) | I165: Advanced | J165: 40 min | K165: Standard attributes | L165: Span names | M165: Modules/08-Evaluation-LLMOps/08-02-Observability-LangSmith-OTel.md | N165: No
A166: Module | B166: 08-02 | C166: 08-Evaluation-LLMOps | D166: 5 | E166: OpenLLMetry | F166: https://github.com/traceloop/openllmetry | G166: =IF(F166="","",HYPERLINK(F166,"Open link")) | H166: =IF(M166="","",IF(Config!$B$6="GitHub",HYPERLINK(Config!$B$5&M166,"Open parent doc"),HYPERLINK("file://"&Config!$B$4&M166,"Open parent doc"))) | I166: Intermediate | J166: 30 min | K166: Auto-instrumentation | L166: Integrations | M166: Modules/08-Evaluation-LLMOps/08-02-Observability-LangSmith-OTel.md | N166: No
A167: Module | B167: 08-03 | C167: 08-Evaluation-LLMOps | D167: 1 | E167: promptfoo Intro | F167: https://www.promptfoo.dev/docs/intro/ | G167: =IF(F167="","",HYPERLINK(F167,"Open link")) | H167: =IF(M167="","",IF(Config!$B$6="GitHub",HYPERLINK(Config!$B$5&M167,"Open parent doc"),HYPERLINK("file://"&Config!$B$4&M167,"Open parent doc"))) | I167: Intro | J167: 25 min | K167: CI testing | L167: Config; assertions | M167: Modules/08-Evaluation-LLMOps/08-03-Guardrails-Ship-Criteria.md | N167: No
A168: Module | B168: 08-03 | C168: 08-Evaluation-LLMOps | D168: 2 | E168: promptfoo Red Team | F168: https://www.promptfoo.dev/docs/red-team/ | G168: =IF(F168="","",HYPERLINK(F168,"Open link")) | H168: =IF(M168="","",IF(Config!$B$6="GitHub",HYPERLINK(Config!$B$5&M168,"Open parent doc"),HYPERLINK("file://"&Config!$B$4&M168,"Open parent doc"))) | I168: Intermediate | J168: 40 min | K168: Safety gates | L168: Attack catalogs | M168: Modules/08-Evaluation-LLMOps/08-03-Guardrails-Ship-Criteria.md | N168: No
... A207: Module | B207: 12-04 | C207: 12-Advanced-Topics | D207: 2 | E207: DSPy GitHub | F207: https://github.com/stanfordnlp/dspy | G207: =IF(F207="","",HYPERLINK(F207,"Open link")) | H207: =IF(M207="","",IF(Config!$B$6="GitHub",HYPERLINK(Config!$B$5&M207,"Open parent doc"),HYPERLINK("file://"&Config!$B$4&M207,"Open parent doc"))) | I207: Intermediate | J207: 30 min | K207: Examples & API | L207: README; tutorials | M207: Modules/12-Advanced-Topics/12-04-DSPy-Programmatic-Prompting.md | N207: No
A208: Module | B208: 12-05 | C208: 12-Advanced-Topics | D208: 1 | E208: https://docs.cursor.com/ | F208: https://docs.cursor.com/ | G208: =IF(F208="","",HYPERLINK(F208,"Open link")) | H208: =IF(M208="","",IF(Config!$B$6="GitHub",HYPERLINK(Config!$B$5&M208,"Open parent doc"),HYPERLINK("file://"&Config!$B$4&M208,"Open parent doc"))) | M208: Modules/12-Advanced-Topics/12-05-AI-Coding-Agents.md | N208: No
A209: Module | B209: 12-05 | C209: 12-Advanced-Topics | D209: 2 | E209: https://docs.cursor.com/context/model-context-protocol | F209: https://docs.cursor.com/context/model-context-protocol | G209: =IF(F209="","",HYPERLINK(F209,"Open link")) | H209: =IF(M209="","",IF(Config!$B$6="GitHub",HYPERLINK(Config!$B$5&M209,"Open parent doc"),HYPERLINK("file://"&Config!$B$4&M209,"Open parent doc"))) | M209: Modules/12-Advanced-Topics/12-05-AI-Coding-Agents.md | N209: No
A210: Module | B210: 12-05 | C210: 12-Advanced-Topics | D210: 3 | E210: https://docs.anthropic.com/en/docs/claude-code/overview | F210: https://docs.anthropic.com/en/docs/claude-code/overview | G210: =IF(F210="","",HYPERLINK(F210,"Open link")) | H210: =IF(M210="","",IF(Config!$B$6="GitHub",HYPERLINK(Config!$B$5&M210,"Open parent doc"),HYPERLINK("file://"&Config!$B$4&M210,"Open parent doc"))) | M210: Modules/12-Advanced-Topics/12-05-AI-Coding-Agents.md | N210: No
A211: Module | B211: 12-05 | C211: 12-Advanced-Topics | D211: 4 | E211: https://docs.anthropic.com/en/docs/claude-code/security | F211: https://docs.anthropic.com/en/docs/claude-code/security | G211: =IF(F211="","",HYPERLINK(F211,"Open link")) | H211: =IF(M211="","",IF(Config!$B$6="GitHub",HYPERLINK(Config!$B$5&M211,"Open parent doc"),HYPERLINK("file://"&Config!$B$4&M211,"Open parent doc"))) | M211: Modules/12-Advanced-Topics/12-05-AI-Coding-Agents.md | N211: No
A212: Module | B212: 12-05 | C212: 12-Advanced-Topics | D212: 5 | E212: https://platform.openai.com/docs/codex | F212: https://platform.openai.com/docs/codex | G212: =IF(F212="","",HYPERLINK(F212,"Open link")) | H212: =IF(M212="","",IF(Config!$B$6="GitHub",HYPERLINK(Config!$B$5&M212,"Open parent doc"),HYPERLINK("file://"&Config!$B$4&M212,"Open parent doc"))) | M212: Modules/12-Advanced-Topics/12-05-AI-Coding-Agents.md | N212: No
A213: Module | B213: 12-05 | C213: 12-Advanced-Topics | D213: 6 | E213: https://platform.openai.com/docs/guides/agents | F213: https://platform.openai.com/docs/guides/agents | G213: =IF(F213="","",HYPERLINK(F213,"Open link")) | H213: =IF(M213="","",IF(Config!$B$6="GitHub",HYPERLINK(Config!$B$5&M213,"Open parent doc"),HYPERLINK("file://"&Config!$B$4&M213,"Open parent doc"))) | M213: Modules/12-Advanced-Topics/12-05-AI-Coding-Agents.md | N213: No
...

Sheet SystemDesign
A1: Design ID | B1: Name | C1: Group | D1: Subgroup | E1: Track | F1: Est Hours | G1: Status | H1: Week Target | I1: Linked Modules | J1: Minutes Spent | K1: Writeup Done | L1: Mock Used | M1: File Path | N1: Open Doc | O1: Notes | P1: Resource Count
A2: AI-Coding-Assistant | B2: System Design — AI Coding Assistant (IDE Copilot) | C2: System Design | D2: Product Design | E2: IC+EM | F2: 3 | G2: Not started | I2: 03-01, 03-03, 12-03 | K2: No | L2: No | M2: System Design/Design-AI-Coding-Assistant.md | N2: =IF(M2="","",IF(Config!$B$6="GitHub",HYPERLINK(Config!$B$5&M2,"Open doc"),HYPERLINK("file://"&Config!$B$4&M2,"Open doc"))) | P2: =COUNTIFS(Resources!A:A,"System Design",Resources!B:B,A2)
A3: AI-Customer-Support | B3: System Design — AI Customer Support (Agent + Human Handoff) | C3: System Design | D3: Product Design | E3: IC+EM | F3: 3 | G3: Not started | I3: 03-04, 04-01, 08-03 | K3: No | L3: No | M3: System Design/Design-AI-Customer-Support.md | N3: =IF(M3="","",IF(Config!$B$6="GitHub",HYPERLINK(Config!$B$5&M3,"Open doc"),HYPERLINK("file://"&Config!$B$4&M3,"Open doc"))) | P3: =COUNTIFS(Resources!A:A,"System Design",Resources!B:B,A3)
A4: AI-Research-Agent | B4: System Design — AI Research Agent (Deep Multi-Step) | C4: System Design | D4: Product Design | E4: IC+EM | F4: 3 | G4: Not started | I4: 12-01, 05-02, 08-01 | K4: No | L4: No | M4: System Design/Design-AI-Research-Agent.md | N4: =IF(M4="","",IF(Config!$B$6="GitHub",HYPERLINK(Config!$B$5&M4,"Open doc"),HYPERLINK("file://"&Config!$B$4&M4,"Open doc"))) | P4: =COUNTIFS(Resources!A:A,"System Design",Resources!B:B,A4)
A5: AI-Search-Engine | B5: System Design — AI Search Engine (Answer + Citations) | C5: System Design | D5: Product Design | E5: IC+EM | F5: 3 | G5: Not started | I5: 04-03, 04-04, 10-04 | K5: No | L5: No | M5: System Design/Design-AI-Search-Engine.md | N5: =IF(M5="","",IF(Config!$B$6="GitHub",HYPERLINK(Config!$B$5&M5,"Open doc"),HYPERLINK("file://"&Config!$B$4&M5,"Open doc"))) | P5: =COUNTIFS(Resources!A:A,"System Design",Resources!B:B,A5)
A6: AI-Voice-Assistant | B6: System Design — AI Voice Assistant (Real-Time Speech) | C6: System Design | D6: Product Design | E6: IC+EM | F6: 3 | G6: Not started | I6: 06-01, 10-03, 08-02 | K6: No | L6: No | M6: System Design/Design-AI-Voice-Assistant.md | N6: =IF(M6="","",IF(Config!$B$6="GitHub",HYPERLINK(Config!$B$5&M6,"Open doc"),HYPERLINK("file://"&Config!$B$4&M6,"Open doc"))) | P6: =COUNTIFS(Resources!A:A,"System Design",Resources!B:B,A6)
A7: ChatGPT | B7: System Design — Design ChatGPT | C7: System Design | D7: Product Design | E7: IC+EM | F7: 3 | G7: Not started | I7: 01-02, 03-01, 08-01, 11-01 | K7: No | L7: No | M7: System Design/Design-ChatGPT.md | N7: =IF(M7="","",IF(Config!$B$6="GitHub",HYPERLINK(Config!$B$5&M7,"Open doc"),HYPERLINK("file://"&Config!$B$4&M7,"Open doc"))) | P7: =COUNTIFS(Resources!A:A,"System Design",Resources!B:B,A7)
A8: Claude | B8: System Design — Design Claude | C8: System Design | D8: Product Design | E8: IC+EM | F8: 3 | G8: Not started | I8: 01-03, 03-02, 07-01, 11-02 | K8: No | L8: No | M8: System Design/Design-Claude.md | N8: =IF(M8="","",IF(Config!$B$6="GitHub",HYPERLINK(Config!$B$5&M8,"Open doc"),HYPERLINK("file://"&Config!$B$4&M8,"Open doc"))) | P8: =COUNTIFS(Resources!A:A,"System Design",Resources!B:B,A8)
A9: Cursor | B9: System Design — Design Cursor | C9: System Design | D9: Product Design | E9: IC+EM | F9: 3 | G9: Not started | I9: 03-03, 04-01, 12-03 | K9: No | L9: No | M9: System Design/Design-Cursor.md | N9: =IF(M9="","",IF(Config!$B$6="GitHub",HYPERLINK(Config!$B$5&M9,"Open doc"),HYPERLINK("file://"&Config!$B$4&M9,"Open doc"))) | P9: =COUNTIFS(Resources!A:A,"System Design",Resources!B:B,A9)
A10: GitHub-Copilot | B10: System Design — Design GitHub Copilot | C10: System Design | D10: Product Design | E10: IC+EM | F10: 3 | G10: Not started | I10: 01-05, 02-02, 10-03 | K10: No | L10: No | M10: System Design/Design-GitHub-Copilot.md | N10: =IF(M10="","",IF(Config!$B$6="GitHub",HYPERLINK(Config!$B$5&M10,"Open doc"),HYPERLINK("file://"&Config!$B$4&M10,"Open doc"))) | P10: =COUNTIFS(Resources!A:A,"System Design",Resources!B:B,A10)
A11: Multi-Agent-Workflow-Engine | B11: System Design — Multi-Agent Workflow Engine | C11: System Design | D11: Product Design | E11: IC+EM | F11: 3 | G11: Not started | I11: 05-01, 07-01, 08-02, 10-02 | K11: No | L11: No | M11: System Design/Design-Multi-Agent-Workflow-Engine.md | N11: =IF(M11="","",IF(Config!$B$6="GitHub",HYPERLINK(Config!$B$5&M11,"Open doc"),HYPERLINK("file://"&Config!$B$4&M11,"Open doc"))) | P11: =COUNTIFS(Resources!A:A,"System Design",Resources!B:B,A11)
A12: Notion-AI | B12: System Design — Notion AI (Workspace Knowledge + Blocks) | C12: System Design | D12: Product Design | E12: IC+EM | F12: 3 | G12: Not started | I12: 04-01, 02-01, 08-01 | K12: No | L12: No | M12: System Design/Design-Notion-AI.md | N12: =IF(M12="","",IF(Config!$B$6="GitHub",HYPERLINK(Config!$B$5&M12,"Open doc"),HYPERLINK("file://"&Config!$B$4&M12,"Open doc"))) | P12: =COUNTIFS(Resources!A:A,"System Design",Resources!B:B,A12)
A13: Perplexity | B13: System Design — Design Perplexity | C13: System Design | D13: Product Design | E13: IC+EM | F13: 3 | G13: Not started | I13: 04-01, 04-03, 12-01 | K13: No | L13: No | M13: System Design/Design-Perplexity.md | N13: =IF(M13="","",IF(Config!$B$6="GitHub",HYPERLINK(Config!$B$5&M13,"Open doc"),HYPERLINK("file://"&Config!$B$4&M13,"Open doc"))) | P13: =COUNTIFS(Resources!A:A,"System Design",Resources!B:B,A13)
A14: Slack-AI | B14: System Design — Slack AI (Enterprise Search + Assist) | C14: System Design | D14: Product Design | E14: IC+EM | F14: 3 | G14: Not started | I14: 04-01, 11-01, 08-03 | K14: No | L14: No | M14: System Design/Design-Slack-AI.md | N14: =IF(M14="","",IF(Config!$B$6="GitHub",HYPERLINK(Config!$B$5&M14,"Open doc"),HYPERLINK("file://"&Config!$B$4&M14,"Open doc"))) | P14: =COUNTIFS(Resources!A:A,"System Design",Resources!B:B,A14)

Sheet LeadershipCareer
A1: Item ID | B1: Name | C1: Group | D1: Subgroup | E1: Track | F1: Est Hours | G1: Status | H1: Linked Modules | I1: STAR Related | J1: File Path | K1: Notes
A2: AI-Governance-Strategy-Metrics | B2: AI Governance, Strategy & Metrics | C2: Leadership & Career | D2: Leadership | E2: EM | F2: 3 | G2: Not started | H2: 00-01, 08-03, 11-01 | I2: No | J2: Leadership/AI-Governance-Strategy-Metrics.md
A3: Behavioral-STAR-Principal-EM | B3: Behavioral STAR — Principal & EM | C3: Leadership & Career | D3: Leadership | E3: EM | F3: 3 | G3: Not started | H3: 00-01, 08-03, 11-01 | I3: Yes | J3: Leadership/Behavioral-STAR-Principal-EM.md
A4: Hiring-AI-Engineers | B4: Hiring AI Engineers | C4: Leadership & Career | D4: Leadership | E4: EM | F4: 3 | G4: Not started | H4: 00-01, 08-03, 11-01 | I4: No | J4: Leadership/Hiring-AI-Engineers.md
A5: Leading-AI-Teams | B5: Leading AI Teams | C5: Leadership & Career | D5: Leadership | E5: EM | F5: 3 | G5: Not started | H5: 00-01, 08-03, 11-01 | I5: No | J5: Leadership/Leading-AI-Teams.md
A6: EM-Interview-Guide | B6: Engineering Manager Interview Guide (AI Era) | C6: Leadership & Career | D6: Career | E6: IC+EM | F6: 3 | G6: Not started | H6: 00-01, 08-03, 11-01 | I6: Yes | J6: Career/EM-Interview-Guide.md
A7: India-AI-Career-Learning-Plan | B7: India AI Career Learning Plan — From Basic Programming, Zero AI | C7: Leadership & Career | D7: Career | E7: IC+EM | F7: 3 | G7: Not started | H7: 00-01, 08-03, 11-01 | I7: No | J7: Career/India-AI-Career-Learning-Plan.md
A8: Principal-Staff-Interview-Guide | B8: Principal / Staff AI Interview Guide | C8: Leadership & Career | D8: Career | E8: IC+EM | F8: 3 | G8: Not started | H8: 00-01, 08-03, 11-01 | I8: Yes | J8: Career/Principal-Staff-Interview-Guide.md

Sheet Weekly
A1: Week | B1: Theme | C1: Group | D1: Module Codes | E1: Project | F1: Interview Focus | G1: Hours Planned | H1: Hours Actual | I1: Status | J1: Modules Total | K1: Modules Done+IR | L1: Week Progress % | M1: Notes
A2: 0 | B2: Foundations — GenAI + craft | C2: 00 Foundations | D2: 00-01, 00-02, 00-03 | E2: Hello-LLM CLI + FastAPI warmup | F2: GenAI vocabulary | G2: 12 | I2: Not started | J2: 3 | K2: =COUNTIFS(Modules!$A:$A,"00-01",Modules!$I:$I,"Done")+COUNTIFS(Modules!$A:$A,"00-01",Modules!$I:$I,"Interview-ready")+COUNTIFS(Modules!$A:$A,"00-02",Modules!$I:$I,"Done")+COUNTIFS(Modules!$A:$A,"00-02",Modules!$I:$I,"Interview-ready")+COUNTIFS(Modules!$A:$A,"00-03",Modules!$I:$I,"Done")+COUNTIFS(Modules!$A:$A,"00-03",Modules!$I:$I,"Interview-ready") | L2: =IF(J2=0,"",K2/J2)
A3: 1 | B3: Foundations — rules + math + BankCo | C3: 00 Foundations | D3: 00-04, 00-05, 00-06 | E3: When-not-to-agent · cosine · BankCo | F3: Rules vs agent | G3: 12 | I3: Not started | J3: 3 | K3: =COUNTIFS(Modules!$A:$A,"00-04",Modules!$I:$I,"Done")+COUNTIFS(Modules!$A:$A,"00-04",Modules!$I:$I,"Interview-ready")+COUNTIFS(Modules!$A:$A,"00-05",Modules!$I:$I,"Done")+COUNTIFS(Modules!$A:$A,"00-05",Modules!$I:$I,"Interview-ready")+COUNTIFS(Modules!$A:$A,"00-06",Modules!$I:$I,"Done")+COUNTIFS(Modules!$A:$A,"00-06",Modules!$I:$I,"Interview-ready") | L3: =IF(J3=0,"",K3/J3)
A4: 2 | B4: LLM Engineering I | C4: 01 LLM Engineering | D4: 01-01, 01-02 | E4: Token cost estimator | F4: Transformer whiteboard | G4: 12 | I4: Not started | J4: 2 | K4: =COUNTIFS(Modules!$A:$A,"01-01",Modules!$I:$I,"Done")+COUNTIFS(Modules!$A:$A,"01-01",Modules!$I:$I,"Interview-ready")+COUNTIFS(Modules!$A:$A,"01-02",Modules!$I:$I,"Done")+COUNTIFS(Modules!$A:$A,"01-02",Modules!$I:$I,"Interview-ready") | L4: =IF(J4=0,"",K4/J4)
A5: 3 | B5: LLM Engineering II | C5: 01 LLM Engineering | D5: 01-03, 01-04, 01-05 | E5: LiteLLM FastAPI router | F5: Inference tradeoffs | G5: 12 | I5: Not started | J5: 3 | K5: =COUNTIFS(Modules!$A:$A,"01-03",Modules!$I:$I,"Done")+COUNTIFS(Modules!$A:$A,"01-03",Modules!$I:$I,"Interview-ready")+COUNTIFS(Modules!$A:$A,"01-04",Modules!$I:$I,"Done")+COUNTIFS(Modules!$A:$A,"01-04",Modules!$I:$I,"Interview-ready")+COUNTIFS(Modules!$A:$A,"01-05",Modules!$I:$I,"Done")+COUNTIFS(Modules!$A:$A,"01-05",Modules!$I:$I,"Interview-ready") | L5: =IF(J5=0,"",K5/J5)
A6: 4 | B6: Prompts & Tools | C6: 02 Prompt Engineering | D6: 02-01, 02-02 | E6: Structured router agent | F6: Tool-calling design | G6: 12 | I6: Not started | J6: 2 | K6: =COUNTIFS(Modules!$A:$A,"02-01",Modules!$I:$I,"Done")+COUNTIFS(Modules!$A:$A,"02-01",Modules!$I:$I,"Interview-ready")+COUNTIFS(Modules!$A:$A,"02-02",Modules!$I:$I,"Done")+COUNTIFS(Modules!$A:$A,"02-02",Modules!$I:$I,"Interview-ready") | L6: =IF(J6=0,"",K6/J6)
A7: 5 | B7: Agents I | C7: 03 Agentic Fundamentals | D7: 03-01, 03-02 | E7: Inquiry routing agent | F7: Agent loop critique | G7: 12 | I7: Not started | J7: 2 | K7: =COUNTIFS(Modules!$A:$A,"03-01",Modules!$I:$I,"Done")+COUNTIFS(Modules!$A:$A,"03-01",Modules!$I:$I,"Interview-ready")+COUNTIFS(Modules!$A:$A,"03-02",Modules!$I:$I,"Done")+COUNTIFS(Modules!$A:$A,"03-02",Modules!$I:$I,"Interview-ready") | L7: =IF(J7=0,"",K7/J7)
A8: 6 | B8: Agents II | C8: 03 Agentic Fundamentals | D8: 03-03, 03-04 | E8: LangGraph + checkpointing | F8: Pattern selection | G8: 12 | I8: Not started | J8: 2 | K8: =COUNTIFS(Modules!$A:$A,"03-03",Modules!$I:$I,"Done")+COUNTIFS(Modules!$A:$A,"03-03",Modules!$I:$I,"Interview-ready")+COUNTIFS(Modules!$A:$A,"03-04",Modules!$I:$I,"Done")+COUNTIFS(Modules!$A:$A,"03-04",Modules!$I:$I,"Interview-ready") | L8: =IF(J8=0,"",K8/J8)
A9: 7 | B9: RAG I | C9: 04 RAG | D9: 04-01, 04-02 | E9: Ingestion + chunking | F9: Chunking tradeoffs | G9: 12 | I9: Not started | J9: 2 | K9: =COUNTIFS(Modules!$A:$A,"04-01",Modules!$I:$I,"Done")+COUNTIFS(Modules!$A:$A,"04-01",Modules!$I:$I,"Interview-ready")+COUNTIFS(Modules!$A:$A,"04-02",Modules!$I:$I,"Done")+COUNTIFS(Modules!$A:$A,"04-02",Modules!$I:$I,"Interview-ready") | L9: =IF(J9=0,"",K9/J9)
A10: 8 | B10: RAG II | C10: 04 RAG | D10: 04-03, 04-04 | E10: Hybrid + rerank + citations | F10: Hallucination control | G10: 12 | I10: Not started | J10: 2 | K10: =COUNTIFS(Modules!$A:$A,"04-03",Modules!$I:$I,"Done")+COUNTIFS(Modules!$A:$A,"04-03",Modules!$I:$I,"Interview-ready")+COUNTIFS(Modules!$A:$A,"04-04",Modules!$I:$I,"Done")+COUNTIFS(Modules!$A:$A,"04-04",Modules!$I:$I,"Interview-ready") | L10: =IF(J10=0,"",K10/J10)
A11: 9 | B11: Multi-Agent | C11: 05 Multi-Agent | D11: 05-01, 05-02, 05-03 | E11: Travel planner multi-agent | F11: Coordination failures | G11: 14 | I11: Not started | J11: 3 | K11: =COUNTIFS(Modules!$A:$A,"05-01",Modules!$I:$I,"Done")+COUNTIFS(Modules!$A:$A,"05-01",Modules!$I:$I,"Interview-ready")+COUNTIFS(Modules!$A:$A,"05-02",Modules!$I:$I,"Done")+COUNTIFS(Modules!$A:$A,"05-02",Modules!$I:$I,"Interview-ready")+COUNTIFS(Modules!$A:$A,"05-03",Modules!$I:$I,"Done")+COUNTIFS(Modules!$A:$A,"05-03",Modules!$I:$I,"Interview-ready") | L11: =IF(J11=0,"",K11/J11)
A12: 10 | B12: Voice / Multimodal | C12: 06 Voice & Multimodal | D12: 06-01, 06-02 | E12: ASR→LLM→TTS bot | F12: Latency budgets | G12: 12 | I12: Not started | J12: 2 | K12: =COUNTIFS(Modules!$A:$A,"06-01",Modules!$I:$I,"Done")+COUNTIFS(Modules!$A:$A,"06-01",Modules!$I:$I,"Interview-ready")+COUNTIFS(Modules!$A:$A,"06-02",Modules!$I:$I,"Done")+COUNTIFS(Modules!$A:$A,"06-02",Modules!$I:$I,"Interview-ready") | L12: =IF(J12=0,"",K12/J12)
A13: 11 | B13: Protocols | C13: 07 Protocols MCP/A2A | D13: 07-01, 07-02, 07-03, 07-04 | E13: MCP + A2A negotiation | F13: Protocol design | G13: 12 | I13: Not started | J13: 4 | K13: =COUNTIFS(Modules!$A:$A,"07-01",Modules!$I:$I,"Done")+COUNTIFS(Modules!$A:$A,"07-01",Modules!$I:$I,"Interview-ready")+COUNTIFS(Modules!$A:$A,"07-02",Modules!$I:$I,"Done")+COUNTIFS(Modules!$A:$A,"07-02",Modules!$I:$I,"Interview-ready")+COUNTIFS(Modules!$A:$A,"07-03",Modules!$I:$I,"Done")+COUNTIFS(Modules!$A:$A,"07-03",Modules!$I:$I,"Interview-ready")+COUNTIFS(Modules!$A:$A,"07-04",Modules!$I:$I,"Done")+COUNTIFS(Modules!$A:$A,"07-04",Modules!$I:$I,"Interview-ready") | L13: =IF(J13=0,"",K13/J13)
A14: 12 | B14: Eval / LLMOps | C14: 08 Eval & LLMOps | D14: 08-01, 08-02, 08-03 | E14: Golden set + ship gate | F14: Eval strategy | G14: 12 | I14: Not started | J14: 3 | K14: =COUNTIFS(Modules!$A:$A,"08-01",Modules!$I:$I,"Done")+COUNTIFS(Modules!$A:$A,"08-01",Modules!$I:$I,"Interview-ready")+COUNTIFS(Modules!$A:$A,"08-02",Modules!$I:$I,"Done")+COUNTIFS(Modules!$A:$A,"08-02",Modules!$I:$I,"Interview-ready")+COUNTIFS(Modules!$A:$A,"08-03",Modules!$I:$I,"Done")+COUNTIFS(Modules!$A:$A,"08-03",Modules!$I:$I,"Interview-ready") | L14: =IF(J14=0,"",K14/J14)
A15: 13 | B15: Fine-Tuning | C15: 09 Fine-Tuning | D15: 09-01, 09-02, 09-03 | E15: LoRA compare | F15: Prompt vs RAG vs FT | G15: 12 | I15: Not started | J15: 3 | K15: =COUNTIFS(Modules!$A:$A,"09-01",Modules!$I:$I,"Done")+COUNTIFS(Modules!$A:$A,"09-01",Modules!$I:$I,"Interview-ready")+COUNTIFS(Modules!$A:$A,"09-02",Modules!$I:$I,"Done")+COUNTIFS(Modules!$A:$A,"09-02",Modules!$I:$I,"Interview-ready")+COUNTIFS(Modules!$A:$A,"09-03",Modules!$I:$I,"Done")+COUNTIFS(Modules!$A:$A,"09-03",Modules!$I:$I,"Interview-ready") | L15: =IF(J15=0,"",K15/J15)
A16: 14 | B16: Production Infra | C16: 10 Production Infra | D16: 10-01, 10-02, 10-03, 10-04 | E16: Dockerized agent API | F16: Cost/latency design | G16: 14 | I16: Not started | J16: 4 | K16: =COUNTIFS(Modules!$A:$A,"10-01",Modules!$I:$I,"Done")+COUNTIFS(Modules!$A:$A,"10-01",Modules!$I:$I,"Interview-ready")+COUNTIFS(Modules!$A:$A,"10-02",Modules!$I:$I,"Done")+COUNTIFS(Modules!$A:$A,"10-02",Modules!$I:$I,"Interview-ready")+COUNTIFS(Modules!$A:$A,"10-03",Modules!$I:$I,"Done")+COUNTIFS(Modules!$A:$A,"10-03",Modules!$I:$I,"Interview-ready")+COUNTIFS(Modules!$A:$A,"10-04",Modules!$I:$I,"Done")+COUNTIFS(Modules!$A:$A,"10-04",Modules!$I:$I,"Interview-ready") | L16: =IF(J16=0,"",K16/J16)
A17: 15 | B17: Security + Advanced | C17: 11 Security & Safety | D17: 11-01, 11-02, 12-01, 12-02 | E17: Red-team + Text2SQL | F17: Safety review | G17: 14 | I17: Not started | J17: 4 | K17: =COUNTIFS(Modules!$A:$A,"11-01",Modules!$I:$I,"Done")+COUNTIFS(Modules!$A:$A,"11-01",Modules!$I:$I,"Interview-ready")+COUNTIFS(Modules!$A:$A,"11-02",Modules!$I:$I,"Done")+COUNTIFS(Modules!$A:$A,"11-02",Modules!$I:$I,"Interview-ready")+COUNTIFS(Modules!$A:$A,"12-01",Modules!$I:$I,"Done")+COUNTIFS(Modules!$A:$A,"12-01",Modules!$I:$I,"Interview-ready")+COUNTIFS(Modules!$A:$A,"12-02",Modules!$I:$I,"Done")+COUNTIFS(Modules!$A:$A,"12-02",Modules!$I:$I,"Interview-ready") | L17: =IF(J17=0,"",K17/J17)
A18: 16 | B18: Advanced + Capstone | C18: 12 Advanced Topics | D18: 12-03, 12-04, 12-05, 12-06 | E18: Capstone vertical slice | F18: Full design interview | G18: 14 | I18: Not started | J18: 4 | K18: =COUNTIFS(Modules!$A:$A,"12-03",Modules!$I:$I,"Done")+COUNTIFS(Modules!$A:$A,"12-03",Modules!$I:$I,"Interview-ready")+COUNTIFS(Modules!$A:$A,"12-04",Modules!$I:$I,"Done")+COUNTIFS(Modules!$A:$A,"12-04",Modules!$I:$I,"Interview-ready")+COUNTIFS(Modules!$A:$A,"12-05",Modules!$I:$I,"Done")+COUNTIFS(Modules!$A:$A,"12-05",Modules!$I:$I,"Interview-ready")+COUNTIFS(Modules!$A:$A,"12-06",Modules!$I:$I,"Done")+COUNTIFS(Modules!$A:$A,"12-06",Modules!$I:$I,"Interview-ready") | L18: =IF(J18=0,"",K18/J18)
A19: 17 | B19: Capstone + Mocks | C19: Capstone | D19: CAPSTONE | E19: Capstone v1 + 4 mocks | F19: Panel simulation | G19: 16 | I19: Not started | J19: 1 | K19: =COUNTIFS(Projects!D:D,"Capstone",Projects!F:F,"Done")+COUNTIFS(Projects!D:D,"Capstone",Projects!F:F,"Interview-ready") | L19: =IF(J19=0,"",K19/J19)

Sheet DailyLog
A1: Date | B1: Week | C1: Module Code | D1: Module Title (auto) | E1: Track Day | F1: Concept min | G1: Build min | H1: Judgment min | I1: Interview min | J1: Total min | K1: Status | L1: Blocker | M1: Win | N1: Next Action
B2: =IF(C2="","",IFERROR(VLOOKUP(C2,Modules!$A:$F,6,FALSE),"")) | D2: =IF(C2="","",IFERROR(VLOOKUP(C2,Modules!$A:$B,2,FALSE),"")) | J2: =SUM(F2:I2) | K2: Not started
B3: =IF(C3="","",IFERROR(VLOOKUP(C3,Modules!$A:$F,6,FALSE),"")) | D3: =IF(C3="","",IFERROR(VLOOKUP(C3,Modules!$A:$B,2,FALSE),"")) | J3: =SUM(F3:I3) | K3: Not started
B4: =IF(C4="","",IFERROR(VLOOKUP(C4,Modules!$A:$F,6,FALSE),"")) | D4: =IF(C4="","",IFERROR(VLOOKUP(C4,Modules!$A:$B,2,FALSE),"")) | J4: =SUM(F4:I4) | K4: Not started
B5: =IF(C5="","",IFERROR(VLOOKUP(C5,Modules!$A:$F,6,FALSE),"")) | D5: =IF(C5="","",IFERROR(VLOOKUP(C5,Modules!$A:$B,2,FALSE),"")) | J5: =SUM(F5:I5) | K5: Not started
B6: =IF(C6="","",IFERROR(VLOOKUP(C6,Modules!$A:$F,6,FALSE),"")) | D6: =IF(C6="","",IFERROR(VLOOKUP(C6,Modules!$A:$B,2,FALSE),"")) | J6: =SUM(F6:I6) | K6: Not started
B7: =IF(C7="","",IFERROR(VLOOKUP(C7,Modules!$A:$F,6,FALSE),"")) | D7: =IF(C7="","",IFERROR(VLOOKUP(C7,Modules!$A:$B,2,FALSE),"")) | J7: =SUM(F7:I7) | K7: Not started
B8: =IF(C8="","",IFERROR(VLOOKUP(C8,Modules!$A:$F,6,FALSE),"")) | D8: =IF(C8="","",IFERROR(VLOOKUP(C8,Modules!$A:$B,2,FALSE),"")) | J8: =SUM(F8:I8) | K8: Not started
B9: =IF(C9="","",IFERROR(VLOOKUP(C9,Modules!$A:$F,6,FALSE),"")) | D9: =IF(C9="","",IFERROR(VLOOKUP(C9,Modules!$A:$B,2,FALSE),"")) | J9: =SUM(F9:I9) | K9: Not started
B10: =IF(C10="","",IFERROR(VLOOKUP(C10,Modules!$A:$F,6,FALSE),"")) | D10: =IF(C10="","",IFERROR(VLOOKUP(C10,Modules!$A:$B,2,FALSE),"")) | J10: =SUM(F10:I10) | K10: Not started
B11: =IF(C11="","",IFERROR(VLOOKUP(C11,Modules!$A:$F,6,FALSE),"")) | D11: =IF(C11="","",IFERROR(VLOOKUP(C11,Modules!$A:$B,2,FALSE),"")) | J11: =SUM(F11:I11) | K11: Not started
B12: =IF(C12="","",IFERROR(VLOOKUP(C12,Modules!$A:$F,6,FALSE),"")) | D12: =IF(C12="","",IFERROR(VLOOKUP(C12,Modules!$A:$B,2,FALSE),"")) | J12: =SUM(F12:I12) | K12: Not started
B13: =IF(C13="","",IFERROR(VLOOKUP(C13,Modules!$A:$F,6,FALSE),"")) | D13: =IF(C13="","",IFERROR(VLOOKUP(C13,Modules!$A:$B,2,FALSE),"")) | J13: =SUM(F13:I13) | K13: Not started
... B51: =IF(C51="","",IFERROR(VLOOKUP(C51,Modules!$A:$F,6,FALSE),"")) | D51: =IF(C51="","",IFERROR(VLOOKUP(C51,Modules!$A:$B,2,FALSE),"")) | J51: =SUM(F51:I51) | K51: Not started

Sheet Projects
A1: Project ID | B1: Name | C1: Group | D1: Tier | E1: Week | F1: Status | G1: Linked Module Codes | H1: Repo URL | I1: Resume Bullet Ready | J1: Demo Ready | K1: Architecture Review | L1: Code Review | M1: Notes
A2: P01 | B2: Hello-LLM Explain-It Bot | C2: Foundations Projects | D2: Mini | E2: 0 | F2: Not started | G2: 00-01 | I2: No | J2: No | K2: No | L2: No
A3: P01b | B3: BankCo Decision Support | C3: Foundations Projects | D3: Mini | E3: 1 | F3: Not started | G3: 00-04, 00-06 | I3: No | J3: No | K3: No | L3: No
A4: P02 | B4: Token Cost Estimator | C4: LLM Projects | D4: Mini | E4: 2 | F4: Not started | G4: 01-02 | I4: No | J4: No | K4: No | L4: No
A5: P03 | B5: LiteLLM Gateway | C5: LLM Projects | D5: Mini | E5: 3 | F5: Not started | G5: 01-03, 01-04 | I5: No | J5: No | K5: No | L5: No
A6: P04 | B6: Structured Router Agent | C6: Agent Projects | D6: Intermediate | E6: 4 | F6: Not started | G6: 02-02, 03-04 | I6: No | J6: No | K6: No | L6: No
A7: P05 | B7: Inquiry Routing Agent | C7: Agent Projects | D7: Intermediate | E7: 5 | F7: Not started | G7: 03-01, 03-02 | I7: No | J7: No | K7: No | L7: No
A8: P06 | B8: LangGraph Production Agent | C8: Agent Projects | D8: Intermediate | E8: 6 | F8: Not started | G8: 03-03 | I8: No | J8: No | K8: No | L8: No
A9: P07 | B9: NovaCart RAG Assistant | C9: RAG Projects | D9: Production | E9: 8 | F9: Not started | G9: 04-01, 04-02, 04-03 | I9: No | J9: No | K9: No | L9: No
A10: P08 | B10: Multi-Agent Travel Planner | C10: Multi-Agent Projects | D10: Production | E10: 9 | F10: Not started | G10: 05-01, 05-02 | I10: No | J10: No | K10: No | L10: No
A11: P09 | B11: Voice Bot | C11: Multimodal Projects | D11: Intermediate | E11: 10 | F11: Not started | G11: 06-01 | I11: No | J11: No | K11: No | L11: No
A12: P10 | B12: MCP + Negotiation Sim | C12: Protocol Projects | D12: Production | E12: 11 | F12: Not started | G12: 07-01, 07-02, 07-03 | I12: No | J12: No | K12: No | L12: No
A13: P11 | B13: Eval Harness + Ship Gate | C13: LLMOps Projects | D13: Production | E13: 12 | F13: Not started | G13: 08-01, 08-03 | I13: No | J13: No | K13: No | L13: No
... A16: P14 | B16: Capstone Multi-Agent System | C16: Capstone | D16: Capstone | E16: 17 | F16: Not started | G16: 05-01, 04-01, 08-01, 11-01 | I16: No | J16: No | K16: No | L16: No

Sheet Interviews
A1: Mock # | B1: Date | C1: Type | D1: Role Target | E1: Score Avg | F1: Weak Dimension | G1: Linked Modules | H1: Linked Design | I1: What Went Well | J1: Critical Miss | K1: Retest Date | L1: Status | M1: Notes
A2: 1 | C2: Senior AI | F2: IC-AG | G2: 03-01, 03-02 | L2: Planned
A3: 2 | C3: Staff AI | F3: IC-AR | G3: 04-01, 04-03 | L3: Planned
A4: 3 | C4: Principal Design | F4: IC-COST | G4: 05-01, 10-03 | H4: Cursor | L4: Planned
A5: 4 | C5: EM Behavioral | F5: EM-PEO | L5: Planned
A6: 5 | C6: Staff+Security | F6: IC-SEC | G6: 11-01, 11-02 | L6: Planned
A7: 6 | C7: EM Execution | F7: EM-EXE | L7: Planned
A8: 7 | C8: Full Panel | F8: IC-COM | G8: 03-03, 08-01 | H8: ChatGPT | L8: Planned
A9: 8 | C9: Offer Rehearsal | F9: EM-ROI | L9: Planned

Sheet STAR
A1: Story ID | B1: Title | C1: Pattern | D1: Group | E1: Role Angle | F1: Status | G1: Strength 1-5 | H1: Linked Modules | I1: Last Practiced | J1: Situation | K1: Task | L1: Action | M1: Result | N1: Notes
A2: S01 | B2: Led AI feature idea→launch | C2: Project Experience | D2: Delivery | E2: Both | F2: Draft | H2: 12-06, 08-03
A3: S02 | B3: Cross-team alignment conflict | C3: Conflict Resolution | D3: People | E3: EM | F3: Draft | H3: 05-01
A4: S03 | B4: Missed deadline recovery | C4: Execution | D4: Delivery | E4: Both | F4: Draft | H4: 10-02
A5: S04 | B5: Hired/leveled AI engineer | C5: Hiring | D5: People | E5: EM | F5: Draft | H5: 08-01
A6: S05 | B6: Hallucination/prod incident | C6: Technical Judgment | D6: Tech | E6: IC | F6: Draft | H6: 04-01, 11-02
A7: S06 | B7: Said no to fine-tune/multi-agent | C7: Technical Judgment | D7: Tech | E7: IC | F7: Draft | H7: 09-02, 05-01
A8: S07 | B8: Influenced without authority | C8: Cross-Functional | D8: People | E8: Both | F8: Draft | H8: 12-06
A9: S08 | B9: Built mentorship rituals | C9: Leadership Profile | D9: People | E9: EM | F9: Draft | H9: 08-03

Sheet _Helper
A1: Code | B1: Title | C1: Group | D1: Week | E1: Status | F1: Include | G1: Rank
A2: 00-01 | B2: 00-01 — GenAI From Scratch: Core Ideas | C2: 00 Foundations | D2: 0 | E2: =IFERROR(VLOOKUP(A2,Modules!$A:$I,9,FALSE),"") | F2: =IF(OR(E2="Not started",E2="In progress"),1,0) | G2: =IF(F2=0,"",COUNTIFS($F$2:F2,1))
A3: 00-02 | B3: 00-02 — Python for AI Engineering | C3: 00 Foundations | D3: 0 | E3: =IFERROR(VLOOKUP(A3,Modules!$A:$I,9,FALSE),"") | F3: =IF(OR(E3="Not started",E3="In progress"),1,0) | G3: =IF(F3=0,"",COUNTIFS($F$2:F3,1))
